<mujoco model="aubo_i20">
  <compiler angle="radian" assetdir="meshes" texturedir="meshes" discardvisual="false" autolimits="true" eulerseq="zyx"/>
  <option timestep="0.002" tolerance="0.0000000001" impratio="200" noslip_iterations="100000"/>
  <visual>
    <rgba contactpoint="0.1 0.8 0.2 1" contactforce="0.7 0.5 0.4 1"/>
    <scale forcewidth="0.04" contactwidth="0.15" contactheight="0.01"/>
  </visual>
  <asset>
    <mesh name="link0" file="link0.STL"/>
    <mesh name="link1" file="link1.STL"/>
    <mesh name="link2" file="link2.STL"/>
    <mesh name="link3" file="link3.STL"/>
    <mesh name="link4" file="link4.STL"/>
    <mesh name="link5" file="link5.STL"/>
    <mesh name="link6" file="link6.STL"/>
  </asset>

  <asset>
    <texture type="skybox" builtin="gradient" rgb1="0.3 0.5 0.7" rgb2="0 0 0" width="512"
        height="3072"/>
    <texture type="2d" name="groundplane" builtin="checker" mark="edge" rgb1="0.2 0.3 0.4"
        rgb2="0.1 0.2 0.3" markrgb="0.8 0.8 0.8" width="300" height="300"/>
    <material name="groundplane" texture="groundplane" texuniform="true" texrepeat="5 5"  reflectance="0.0"/>
  </asset>
  <default>
    <default class="arm">
      <default class="visual">
        <geom type="mesh" contype="0" conaffinity="0" group="2"/>
      </default>
    </default>
  </default>

  <!-- <worldbody>
    <light pos="0 0 1.5" dir="0 0 -1" directional="true"/>
    <geom name="floor" size="0 0 0.05" type="plane" material="groundplane"/>   
  </worldbody> -->
 

  <worldbody>
    <geom type="mesh" rgba="1 1 1 1" mesh="link0" class="visual"/>
    <body name="shoulder_Link" pos="0 0 0.1855" quat="1 0 0 0">
      <inertial pos="-2.839e-05 0.00362627 -0.0287715" quat="0.58109 -0.04903 0.0650076 0.809756" mass="15.9876" diaginertia="0.081353 0.0813027 0.0672485"/>
      <joint name="shoulder_joint" pos="0 0 0" axis="0 0 1" limited="true" range="-6.28319 6.28319" damping="0.2" frictionloss="0.5"/>
      <geom type="mesh" rgba="1 1 1 1" mesh="link1" class="visual"/>
      <body name="upperArm_Link" pos="0 0.177 0" quat="0.5 -0.5 -0.5 -0.5">
        <inertial pos="0.318043 1.805e-05 0.0194444" quat="0.503149 0.496861 0.497828 0.502133" mass="33.2783" diaginertia="4.48182 4.44672 0.166633"/>
        <joint name="upperArm_joint" pos="0 0 0" axis="0 0 1" limited="true" range="-6.28319 6.28319"  damping="0.2" frictionloss="0.5"/>
        <geom type="mesh" rgba="1 1 1 1" mesh="link2" class="visual"/>
        <body name="foreArm_Link" pos="0.803 0 0" quat="0 -1 0 0">
          <inertial pos="0.488002 -1.248e-05 0.116204" quat="0.498757 0.501263 0.500101 0.499876" mass="6.70688" diaginertia="0.528953 0.527358 0.013609"/>
          <joint name="foreArm_joint" pos="0 0 0" axis="0 0 1" limited="true" range="-6.28319 6.28319"  damping="0.2" frictionloss="0.5"/>
          <geom type="mesh" rgba="1 1 1 1" mesh="link3" class="visual"/>
          <body name="wrist1_Link" pos="0.72 0 0" quat="0 0.707107 0.707107 0">
            <inertial pos="1.566e-05 0.0157158 -0.0018517" quat="0.680633 0.732597 -0.00393999 0.00503225" mass="3.2573" diaginertia="0.0057169 0.0056458 0.00385307"/>
            <joint name="wrist1_joint" pos="0 0 0" axis="0 0 1" limited="true" range="-6.28319 6.28319"  damping="0.2" frictionloss="0.5"/>
            <geom type="mesh" rgba="1 1 1 1" mesh="link4" class="visual"/>
            <body name="wrist2_Link" pos="0 0.127 0" quat="0.707107 -0.707107 0 0">
              <inertial pos="-1.566e-05 -0.0157158 -0.0018517" quat="0.732595 0.680635 0.00503228 -0.00393998" mass="3.2573" diaginertia="0.0057169 0.0056458 0.00385307"/>
              <joint name="wrist2_joint" pos="0 0 0" axis="0 0 1" limited="true" range="-6.28319 6.28319"  damping="0.2" frictionloss="0.5"/>
              <geom type="mesh" rgba="1 1 1 1" mesh="link5" class="visual"/>
              <body name="wrist3_Link" pos="0 -0.1063 0" quat="0.707107 0.707107 0 0">
                <inertial pos="0.00046615 -0.00036717 -0.0184927" quat="-0.0125782 0.707948 0.0072675 0.706115" mass="0.317904" diaginertia="0.00037056 0.000219305 0.000214425"/>
                <joint name="wrist3_joint" pos="0 0 0" axis="0 0 1" limited="true" range="-6.28319 6.28319"  damping="0.2" frictionloss="0.5"/>
                <geom type="mesh" rgba="1 1 1 1" mesh="link6" class="visual"/>
                <site name="teminal_site" size="0.02" pos="0 0 -0.0" group="2"/>
              </body>
            </body>
          </body>
        </body>
      </body>
    </body>
  </worldbody>


  <actuator>
    <motor name="j0" joint="shoulder_joint" forcerange="-557 557"/>
    <motor name="j1" joint="upperArm_joint" forcerange="-557 557"/>
    <motor name="j2" joint="foreArm_joint" forcerange="-267 267"/>
    <motor name="j3" joint="wrist1_joint" forcerange="-61 61"/>
    <motor name="j4" joint="wrist2_joint" forcerange="-61 61"/>
    <motor name="j5" joint="wrist3_joint" forcerange="-61 61"/>
  </actuator>
  <sensor>
    <framequat name="terminator" objtype="site" objname="teminal_site"/>
  </sensor>
</mujoco>
